2024-05-16 23:12:03,636 INFO    MainThread:15958 [wandb_setup.py:_flush():76] Configure stats pid to 15958
2024-05-16 23:12:03,636 INFO    MainThread:15958 [wandb_setup.py:_flush():76] Loading settings from /home/yimeng/.config/wandb/settings
2024-05-16 23:12:03,636 INFO    MainThread:15958 [wandb_setup.py:_flush():76] Loading settings from /home/yimeng/DTU-RL-Isaac-Gym-Drone-Env/isaacgymenvs/wandb/settings
2024-05-16 23:12:03,636 INFO    MainThread:15958 [wandb_setup.py:_flush():76] Loading settings from environment variables: {}
2024-05-16 23:12:03,636 INFO    MainThread:15958 [wandb_setup.py:_flush():76] Inferring run settings from compute environment: {'program_relpath': 'isaacgymenvs/train.py', 'program': 'train.py'}
2024-05-16 23:12:03,636 INFO    MainThread:15958 [wandb_init.py:_log_setup():461] Logging user logs to /home/yimeng/DTU-RL-Isaac-Gym-Drone-Env/isaacgymenvs/wandb/run-20240516_231203-uid_DroneHoops_16-23-10-19/logs/debug.log
2024-05-16 23:12:03,636 INFO    MainThread:15958 [wandb_init.py:_log_setup():462] Logging internal logs to /home/yimeng/DTU-RL-Isaac-Gym-Drone-Env/isaacgymenvs/wandb/run-20240516_231203-uid_DroneHoops_16-23-10-19/logs/debug-internal.log
2024-05-16 23:12:03,636 INFO    MainThread:15958 [wandb_init.py:init():495] calling init triggers
2024-05-16 23:12:03,636 INFO    MainThread:15958 [wandb_init.py:init():499] wandb.init called with sweep_config: {}
config: {}
2024-05-16 23:12:03,636 INFO    MainThread:15958 [wandb_init.py:init():548] starting backend
2024-05-16 23:12:03,636 INFO    MainThread:15958 [backend.py:_multiprocessing_setup():99] multiprocessing start_methods=fork,spawn,forkserver, using: fork
2024-05-16 23:12:03,638 INFO    MainThread:15958 [backend.py:ensure_launched():217] starting backend process...
2024-05-16 23:12:03,641 INFO    MainThread:15958 [backend.py:ensure_launched():222] started backend process with pid: 16108
2024-05-16 23:12:03,642 INFO    MainThread:15958 [wandb_init.py:init():558] backend started and connected
2024-05-16 23:12:03,648 INFO    MainThread:15958 [wandb_init.py:init():634] updated telemetry
2024-05-16 23:12:03,650 INFO    MainThread:16108 [internal.py:wandb_internal():93] W&B internal server running at pid: 16108, started at: 2024-05-16 23:12:03.649928
2024-05-16 23:12:03,653 INFO    WriterThread:16108 [datastore.py:open_for_write():75] open: /home/yimeng/DTU-RL-Isaac-Gym-Drone-Env/isaacgymenvs/wandb/run-20240516_231203-uid_DroneHoops_16-23-10-19/run-uid_DroneHoops_16-23-10-19.wandb
2024-05-16 23:12:03,661 INFO    MainThread:15958 [wandb_init.py:init():666] communicating run to backend with 30 second timeout
2024-05-16 23:12:03,665 INFO    SenderThread:16108 [sender.py:_maybe_setup_resume():494] checking resume status for rolando-esq/IsaacGymDrone/uid_DroneHoops_16-23-10-19
2024-05-16 23:12:03,863 ERROR   SenderThread:16108 [internal_api.py:execute():161] 404 response executing GraphQL.
2024-05-16 23:12:03,863 ERROR   SenderThread:16108 [internal_api.py:execute():162] {"errors":[{"message":"project not found","path":["upsertBucket"]}],"data":{"upsertBucket":null}}
2024-05-16 23:12:04,663 INFO    WriterThread:16108 [datastore.py:close():279] close: /home/yimeng/DTU-RL-Isaac-Gym-Drone-Env/isaacgymenvs/wandb/run-20240516_231203-uid_DroneHoops_16-23-10-19/run-uid_DroneHoops_16-23-10-19.wandb
2024-05-16 23:12:04,663 INFO    HandlerThread:16108 [handler.py:finish():806] shutting down handler
2024-05-16 23:12:04,664 ERROR   MainThread:16108 [internal.py:wandb_internal():165] Thread SenderThread:
Traceback (most recent call last):
  File "/home/yimeng/miniconda3/envs/rlgpu/lib/python3.7/site-packages/wandb/sdk/lib/retry.py", line 108, in __call__
    result = self._call_fn(*args, **kwargs)
  File "/home/yimeng/miniconda3/envs/rlgpu/lib/python3.7/site-packages/wandb/sdk/internal/internal_api.py", line 158, in execute
    return self.client.execute(*args, **kwargs)
  File "/home/yimeng/miniconda3/envs/rlgpu/lib/python3.7/site-packages/wandb/vendor/gql-0.2.0/wandb_gql/client.py", line 52, in execute
    result = self._get_result(document, *args, **kwargs)
  File "/home/yimeng/miniconda3/envs/rlgpu/lib/python3.7/site-packages/wandb/vendor/gql-0.2.0/wandb_gql/client.py", line 60, in _get_result
    return self.transport.execute(document, *args, **kwargs)
  File "/home/yimeng/miniconda3/envs/rlgpu/lib/python3.7/site-packages/wandb/vendor/gql-0.2.0/wandb_gql/transport/requests.py", line 39, in execute
    request.raise_for_status()
  File "/home/yimeng/miniconda3/envs/rlgpu/lib/python3.7/site-packages/requests/models.py", line 1021, in raise_for_status
    raise HTTPError(http_error_msg, response=self)
requests.exceptions.HTTPError: 404 Client Error: Not Found for url: https://api.wandb.ai/graphql

During handling of the above exception, another exception occurred:

Traceback (most recent call last):
  File "/home/yimeng/miniconda3/envs/rlgpu/lib/python3.7/site-packages/wandb/apis/normalize.py", line 25, in wrapper
    return func(*args, **kwargs)
  File "/home/yimeng/miniconda3/envs/rlgpu/lib/python3.7/site-packages/wandb/sdk/internal/internal_api.py", line 1341, in upsert_run
    response = self.gql(mutation, variable_values=variable_values, **kwargs)
  File "/home/yimeng/miniconda3/envs/rlgpu/lib/python3.7/site-packages/wandb/sdk/lib/retry.py", line 124, in __call__
    if not check_retry_fn(e):
  File "/home/yimeng/miniconda3/envs/rlgpu/lib/python3.7/site-packages/wandb/util.py", line 887, in no_retry_auth
    raise CommError("Permission denied, ask the project owner to grant you access")
wandb.errors.CommError: Permission denied, ask the project owner to grant you access

During handling of the above exception, another exception occurred:

Traceback (most recent call last):
  File "/home/yimeng/miniconda3/envs/rlgpu/lib/python3.7/site-packages/wandb/sdk/internal/internal_util.py", line 51, in run
    self._run()
  File "/home/yimeng/miniconda3/envs/rlgpu/lib/python3.7/site-packages/wandb/sdk/internal/internal_util.py", line 102, in _run
    self._process(record)
  File "/home/yimeng/miniconda3/envs/rlgpu/lib/python3.7/site-packages/wandb/sdk/internal/internal.py", line 310, in _process
    self._sm.send(record)
  File "/home/yimeng/miniconda3/envs/rlgpu/lib/python3.7/site-packages/wandb/sdk/internal/sender.py", line 238, in send
    send_handler(record)
  File "/home/yimeng/miniconda3/envs/rlgpu/lib/python3.7/site-packages/wandb/sdk/internal/sender.py", line 696, in send_run
    self._init_run(run, config_value_dict)
  File "/home/yimeng/miniconda3/envs/rlgpu/lib/python3.7/site-packages/wandb/sdk/internal/sender.py", line 734, in _init_run
    commit=run.git.last_commit or None,
  File "/home/yimeng/miniconda3/envs/rlgpu/lib/python3.7/site-packages/wandb/apis/normalize.py", line 61, in wrapper
    raise CommError(message, err).with_traceback(sys.exc_info()[2])
  File "/home/yimeng/miniconda3/envs/rlgpu/lib/python3.7/site-packages/wandb/apis/normalize.py", line 25, in wrapper
    return func(*args, **kwargs)
  File "/home/yimeng/miniconda3/envs/rlgpu/lib/python3.7/site-packages/wandb/sdk/internal/internal_api.py", line 1341, in upsert_run
    response = self.gql(mutation, variable_values=variable_values, **kwargs)
  File "/home/yimeng/miniconda3/envs/rlgpu/lib/python3.7/site-packages/wandb/sdk/lib/retry.py", line 124, in __call__
    if not check_retry_fn(e):
  File "/home/yimeng/miniconda3/envs/rlgpu/lib/python3.7/site-packages/wandb/util.py", line 887, in no_retry_auth
    raise CommError("Permission denied, ask the project owner to grant you access")
wandb.errors.CommError: Permission denied, ask the project owner to grant you access
2024-05-16 23:12:33,662 INFO    MainThread:15958 [interface_shared.py:_communicate_run():326] couldn't get run from backend
2024-05-16 23:12:33,662 ERROR   MainThread:15958 [wandb_init.py:init():674] backend process timed out
2024-05-16 23:12:33,662 ERROR   MainThread:15958 [wandb_init.py:init():685] encountered error: Error communicating with wandb process
2024-05-16 23:12:33,666 ERROR   MainThread:15958 [wandb_init.py:init():1070] error
Traceback (most recent call last):
  File "/home/yimeng/miniconda3/envs/rlgpu/lib/python3.7/site-packages/wandb/sdk/wandb_init.py", line 1043, in init
    run = wi.init()
  File "/home/yimeng/miniconda3/envs/rlgpu/lib/python3.7/site-packages/wandb/sdk/wandb_init.py", line 689, in init
    backend.cleanup()
  File "/home/yimeng/miniconda3/envs/rlgpu/lib/python3.7/site-packages/wandb/sdk/backend/backend.py", line 246, in cleanup
    self.interface.join()
  File "/home/yimeng/miniconda3/envs/rlgpu/lib/python3.7/site-packages/wandb/sdk/interface/interface_shared.py", line 475, in join
    super().join()
  File "/home/yimeng/miniconda3/envs/rlgpu/lib/python3.7/site-packages/wandb/sdk/interface/interface.py", line 666, in join
    _ = self._communicate_shutdown()
  File "/home/yimeng/miniconda3/envs/rlgpu/lib/python3.7/site-packages/wandb/sdk/interface/interface_shared.py", line 472, in _communicate_shutdown
    _ = self._communicate(record)
  File "/home/yimeng/miniconda3/envs/rlgpu/lib/python3.7/site-packages/wandb/sdk/interface/interface_shared.py", line 226, in _communicate
    return self._communicate_async(rec, local=local).get(timeout=timeout)
  File "/home/yimeng/miniconda3/envs/rlgpu/lib/python3.7/site-packages/wandb/sdk/interface/interface_shared.py", line 231, in _communicate_async
    raise Exception("The wandb backend process has shutdown")
Exception: The wandb backend process has shutdown
