2024-05-16 23:03:06,912 INFO    MainThread:15624 [internal.py:wandb_internal():93] W&B internal server running at pid: 15624, started at: 2024-05-16 23:03:06.912020
2024-05-16 23:03:06,914 DEBUG   SenderThread:15624 [sender.py:send():236] send: header
2024-05-16 23:03:06,914 INFO    WriterThread:15624 [datastore.py:open_for_write():75] open: /home/yimeng/DTU-RL-Isaac-Gym-Drone-Env/isaacgymenvs/wandb/run-20240516_230306-uid_DroneHoops_16-22-57-46/run-uid_DroneHoops_16-22-57-46.wandb
2024-05-16 23:03:06,922 DEBUG   SenderThread:15624 [sender.py:send():236] send: run
2024-05-16 23:03:06,923 INFO    SenderThread:15624 [sender.py:_maybe_setup_resume():494] checking resume status for rolando-esq/IsaacGymDrone/uid_DroneHoops_16-22-57-46
2024-05-16 23:03:07,154 ERROR   SenderThread:15624 [internal_api.py:execute():161] 404 response executing GraphQL.
2024-05-16 23:03:07,154 ERROR   SenderThread:15624 [internal_api.py:execute():162] {"errors":[{"message":"project not found","path":["upsertBucket"]}],"data":{"upsertBucket":null}}
2024-05-16 23:03:07,922 INFO    HandlerThread:15624 [handler.py:finish():806] shutting down handler
2024-05-16 23:03:07,922 INFO    WriterThread:15624 [datastore.py:close():279] close: /home/yimeng/DTU-RL-Isaac-Gym-Drone-Env/isaacgymenvs/wandb/run-20240516_230306-uid_DroneHoops_16-22-57-46/run-uid_DroneHoops_16-22-57-46.wandb
2024-05-16 23:03:07,932 ERROR   MainThread:15624 [internal.py:wandb_internal():165] Thread SenderThread:
Traceback (most recent call last):
  File "/home/yimeng/miniconda3/envs/rlgpu/lib/python3.7/site-packages/wandb/sdk/lib/retry.py", line 108, in __call__
    result = self._call_fn(*args, **kwargs)
  File "/home/yimeng/miniconda3/envs/rlgpu/lib/python3.7/site-packages/wandb/sdk/internal/internal_api.py", line 158, in execute
    return self.client.execute(*args, **kwargs)
  File "/home/yimeng/miniconda3/envs/rlgpu/lib/python3.7/site-packages/wandb/vendor/gql-0.2.0/wandb_gql/client.py", line 52, in execute
    result = self._get_result(document, *args, **kwargs)
  File "/home/yimeng/miniconda3/envs/rlgpu/lib/python3.7/site-packages/wandb/vendor/gql-0.2.0/wandb_gql/client.py", line 60, in _get_result
    return self.transport.execute(document, *args, **kwargs)
  File "/home/yimeng/miniconda3/envs/rlgpu/lib/python3.7/site-packages/wandb/vendor/gql-0.2.0/wandb_gql/transport/requests.py", line 39, in execute
    request.raise_for_status()
  File "/home/yimeng/miniconda3/envs/rlgpu/lib/python3.7/site-packages/requests/models.py", line 1021, in raise_for_status
    raise HTTPError(http_error_msg, response=self)
requests.exceptions.HTTPError: 404 Client Error: Not Found for url: https://api.wandb.ai/graphql

During handling of the above exception, another exception occurred:

Traceback (most recent call last):
  File "/home/yimeng/miniconda3/envs/rlgpu/lib/python3.7/site-packages/wandb/apis/normalize.py", line 25, in wrapper
    return func(*args, **kwargs)
  File "/home/yimeng/miniconda3/envs/rlgpu/lib/python3.7/site-packages/wandb/sdk/internal/internal_api.py", line 1341, in upsert_run
    response = self.gql(mutation, variable_values=variable_values, **kwargs)
  File "/home/yimeng/miniconda3/envs/rlgpu/lib/python3.7/site-packages/wandb/sdk/lib/retry.py", line 124, in __call__
    if not check_retry_fn(e):
  File "/home/yimeng/miniconda3/envs/rlgpu/lib/python3.7/site-packages/wandb/util.py", line 887, in no_retry_auth
    raise CommError("Permission denied, ask the project owner to grant you access")
wandb.errors.CommError: Permission denied, ask the project owner to grant you access

During handling of the above exception, another exception occurred:

Traceback (most recent call last):
  File "/home/yimeng/miniconda3/envs/rlgpu/lib/python3.7/site-packages/wandb/sdk/internal/internal_util.py", line 51, in run
    self._run()
  File "/home/yimeng/miniconda3/envs/rlgpu/lib/python3.7/site-packages/wandb/sdk/internal/internal_util.py", line 102, in _run
    self._process(record)
  File "/home/yimeng/miniconda3/envs/rlgpu/lib/python3.7/site-packages/wandb/sdk/internal/internal.py", line 310, in _process
    self._sm.send(record)
  File "/home/yimeng/miniconda3/envs/rlgpu/lib/python3.7/site-packages/wandb/sdk/internal/sender.py", line 238, in send
    send_handler(record)
  File "/home/yimeng/miniconda3/envs/rlgpu/lib/python3.7/site-packages/wandb/sdk/internal/sender.py", line 696, in send_run
    self._init_run(run, config_value_dict)
  File "/home/yimeng/miniconda3/envs/rlgpu/lib/python3.7/site-packages/wandb/sdk/internal/sender.py", line 734, in _init_run
    commit=run.git.last_commit or None,
  File "/home/yimeng/miniconda3/envs/rlgpu/lib/python3.7/site-packages/wandb/apis/normalize.py", line 61, in wrapper
    raise CommError(message, err).with_traceback(sys.exc_info()[2])
  File "/home/yimeng/miniconda3/envs/rlgpu/lib/python3.7/site-packages/wandb/apis/normalize.py", line 25, in wrapper
    return func(*args, **kwargs)
  File "/home/yimeng/miniconda3/envs/rlgpu/lib/python3.7/site-packages/wandb/sdk/internal/internal_api.py", line 1341, in upsert_run
    response = self.gql(mutation, variable_values=variable_values, **kwargs)
  File "/home/yimeng/miniconda3/envs/rlgpu/lib/python3.7/site-packages/wandb/sdk/lib/retry.py", line 124, in __call__
    if not check_retry_fn(e):
  File "/home/yimeng/miniconda3/envs/rlgpu/lib/python3.7/site-packages/wandb/util.py", line 887, in no_retry_auth
    raise CommError("Permission denied, ask the project owner to grant you access")
wandb.errors.CommError: Permission denied, ask the project owner to grant you access
